Workbook

Sheet Project Instructions
A1: PR. 2 Analyzer
A2: Topics: - Conditional Formatting - WHAT IF Analysis - Linear Regression (Using Data Analysis Toolpak) - Data Analysis Feature (Descriptive Stats, Regression, Histogram) - Data Storytelling - Add Symbols or Arrows in Custom Formatting - Create Timestamp - Find High-Value Customers using Groupby(), index(), and match() combination - Advanced Descriptive Analytics - Pivot Table with Dashboard - Creating bar charts - Creating line charts - Creating pie charts Main Tasks: 1. Apply conditional formatting to highlight top 10 customers based on total purchase. 2. Perform WHAT IF Analysis to see impact of changing discount on total profit. 3. Use Data Analysis Toolpak to run Linear Regression (Profit vs Sales). 4. Use 'Descriptive Statistics' from Analysis Toolpak on the dataset. 5. Add up/down arrows on monthly sales growth. 6. Create a timestamp column using NOW(). 7. Identify high-value customers using index(), match(), and filters. 8. Create Pivot Table to analyze total sales by region and product. 9. Create bar, line, and pie charts to visualize KPIs. 10. Summarize insights using a dashboard. Deliverable: Complete the given worksheet by applying the required formulas in respective sheets.

Sheet Dataset
A1: Customer_ID | B1: Customer_Name | C1: Region | D1: Product_Category | E1: Sales | F1: Quantity | G1: Discount | H1: Order_Date | I1: Profit
A2: CUST019 | B2: James Davis | C2: West | D2: Books | E2: 1036.09 | F2: 4 | G2: 0.2 | H2: 45392 | I2: 331.55
A3: CUST012 | B3: Robert Anderson | C3: West | D3: Clothing | E3: 1101.28 | F3: 3 | G3: 0.2 | H3: 45393 | I3: 440.51
A4: CUST017 | B4: James Taylor | C4: East | D4: Books | E4: 713.34 | F4: 17 | G4: 0 | H4: 45396 | I4: 285.34
A5: CUST005 | B5: Robert Anderson | C5: South | D5: Electronics | E5: 760.93 | F5: 4 | G5: 0.15 | H5: 45396 | I5: 161.7
A6: CUST030 | B6: James Wilson | C6: North | D6: Books | E6: 847 | F6: 12 | G6: 0.2 | H6: 45397 | I6: 271.04
A7: CUST007 | B7: Michael Anderson | C7: North | D7: Furniture | E7: 965.64 | F7: 8 | G7: 0.1 | H7: 45398 | I7: 304.18
A8: CUST001 | B8: Linda Wilson | C8: West | D8: Electronics | E8: 1317.53 | F8: 12 | G8: 0.05 | H8: 45398 | I8: 312.91
A9: CUST026 | B9: Mary Davis | C9: East | D9: Furniture | E9: 1074.47 | F9: 6 | G9: 0.2 | H9: 45401 | I9: 300.85
A10: CUST009 | B10: Linda Jackson | C10: Central | D10: Books | E10: 501.54 | F10: 11 | G10: 0.05 | H10: 45401 | I10: 190.59
A11: CUST010 | B11: David Thomas | C11: Central | D11: Clothing | E11: 737.31 | F11: 2 | G11: 0.05 | H11: 45401 | I11: 350.22
A12: CUST014 | B12: Emma Davis | C12: West | D12: Office Supplies | E12: 1572.82 | F12: 6 | G12: 0.05 | H12: 45402 | I12: 672.38
A13: CUST014 | B13: David Thomas | C13: Central | D13: Books | E13: 1343.13 | F13: 14 | G13: 0.15 | H13: 45404 | I13: 456.66
... A201: CUST016 | B201: David Thomas | C201: South | D201: Clothing | E201: 928.32 | F201: 2 | G201: 0.05 | H201: 45754 | I201: 440.95

Sheet Conditional Statement
A3: Row Labels | B3: Sum of Sales
A4: CUST015 | B4: 11611.06
A5: CUST028 | B5: 10293.87
A6: CUST007 | B6: 9941.88
A7: CUST008 | B7: 9760.8
A8: CUST026 | B8: 9371.81
A9: CUST021 | B9: 8740.18
A10: CUST003 | B10: 8490.18
A11: CUST012 | B11: 8339
A12: CUST030 | B12: 7928.71
A13: CUST004 | B13: 7813.59
A14: CUST024 | B14: 7583.13
A15: CUST014 | B15: 6729.89
... A34: Grand Total | B34: 195217.76

Sheet What If Analysis
A1: WHAT-IF ANALYSIS
A3: Total Sales | B3: =SUM(Dataset!E:E) -> 195217.76
A4: Total Profit | B4: =SUM(Dataset!I:I) -> 68287.01
A5: Current Average Discount | B5: =AVERAGE(Dataset!G:G) -> 0.09725
A6: New Discount | B6: 0.1
A7: Adjusted Profit | B7: =B4+(B5-B6)*B3 -> 67750.161

Sheet Scenario Summary
B2: Scenario Summary
D3: Current Values: | E3: Base Case | F3: Best Case | G3: Worst Case
E4: Created by Shrey patel on 29-10-2026 | F4: Created by Shrey patel on 29-10-2026 | G4: Created by Shrey patel on 29-10-2026
B5: Changing Cells:
C6: $B$6 | D6: 0.1 | E6: 0.1 | F6: 0.05 | G6: 0.2
B7: Result Cells:
C8: $B$7 | D8: 67750.161 | E8: 67750.161 | F8: 77511.049 | G8: 48228.385
B9: Notes: Current Values column represents values of changing cells at
B10: time Scenario Summary Report was created. Changing cells for each
B11: scenario are highlighted in gray.

Sheet Linear Regression
A1: Sales | B1: Profit | D1: SUMMARY OUTPUT
A2: 1036.09 | B2: 331.55
A3: 1101.28 | B3: 440.51 | D3: Regression Statistics
A4: 713.34 | B4: 285.34 | D4: Multiple R | E4: 0.77340306
A5: 760.93 | B5: 161.7 | D5: R Square | E5: 0.5981523
A6: 847 | B6: 271.04 | D6: Adjusted R Square | E6: 0.59612277
A7: 965.64 | B7: 304.18 | D7: Standard Error | E7: 86.281231
A8: 1317.53 | B8: 312.91 | D8: Observations | E8: 200
A9: 1074.47 | B9: 300.85
A10: 501.54 | B10: 190.59 | D10: ANOVA
A11: 737.31 | B11: 350.22 | E11: df | F11: SS | G11: MS | H11: F | I11: Significance F
A12: 1572.82 | B12: 672.38 | D12: Regression | E12: 1 | F12: 2194058.2 | G12: 2194058.2 | H12: 294.72398 | I12: 4.6269368e-41
A13: 1343.13 | B13: 456.66 | D13: Residual | E13: 198 | F13: 1474001.2 | G13: 7444.4507
A14: 1191.58 | B14: 452.8 | D14: Total | E14: 199 | F14: 3668059.4
A15: 822.28 | B15: 273.41
A16: 521.67 | B16: 155.2 | E16: Coefficients | F16: Standard Error | G16: t Stat | H16: P-value | I16: Lower 95% | J16: Upper 95% | K16: Lower 95.0% | L16: Upper 95.0%
A17: 1502.93 | B17: 300.59 | D17: Intercept | E17: -1.0315505 | F17: 20.860617 | G17: -0.049449663 | H17: 0.9606108 | I17: -42.169052 | J17: 40.105951 | K17: -42.169052 | L17: 40.105951
A18: 877.58 | B18: 298.38 | D18: Sales | E18: 0.35085599 | F18: 0.020437189 | G18: 17.167527 | H18: 4.6269368e-41 | I18: 0.3105535 | J18: 0.39115848 | K18: 0.3105535 | L18: 0.39115848
A19: 636.7 | B19: 203.74
A20: 1506.14 | B20: 481.96
A21: 645.02 | B21: 161.26
A22: 953.3 | B22: 476.65 | D22: RESIDUAL OUTPUT
A23: 388.56 | B23: 82.57
A24: 743.17 | B24: 297.27 | D24: Observation | E24: Predicted Profit | F24: Residuals
A25: 706.37 | B25: 176.59 | D25: 1 | E25: 362.48683 | F25: -30.93683
A26: 925.31 | B26: 374.75 | D26: 2 | E26: 385.35913 | F26: 55.150868
A27: 1173.12 | B27: 293.28 | D27: 3 | E27: 249.24806 | F27: 36.09194
A28: 675.54 | B28: 236.44 | D28: 4 | E28: 265.9453 | F28: -104.2453
A29: 939.09 | B29: 356.85 | D29: 5 | E29: 296.14347 | F29: -25.103472
A30: 983.34 | B30: 398.25 | D30: 6 | E30: 337.76903 | F30: -33.589026
A31: 801.21 | B31: 160.24 | D31: 7 | E31: 461.23174 | F31: -148.32174
A32: 1450.71 | B32: 326.41 | D32: 8 | E32: 375.95268 | F32: -75.102683
A33: 1023.21 | B33: 388.82 | D33: 9 | E33: 174.93676 | F33: 15.653238
A34: 853.72 | B34: 253.98 | D34: 10 | E34: 257.65808 | F34: 92.561922
A35: 967.89 | B35: 217.78 | D35: 11 | E35: 550.80176 | F35: 121.57824
A36: 1200.9 | B36: 513.38 | D36: 12 | E36: 470.21365 | F36: -13.553653
... A201: 928.32 | B201: 440.95 | D201: 177 | E201: 289.11583 | F201: 41.674174
D202: 178 | E202: 357.62397 | F202: 102.37603
D203: 179 | E203: 384.80127 | F203: 55.078729
D204: 180 | E204: 248.25865 | F204: 7.5313538
...

Sheet Descriptive Statistics
A1: Sales | B1: Profit | C1: Quantity | E1: Sales | G1: Profit | I1: Quantity | L1: Bin | M1: Frequency
A2: 1036.09 | B2: 331.55 | C2: 4 | L2: 258.51 | M2: 1
A3: 1101.28 | B3: 440.51 | C3: 3 | E3: Mean | F3: 976.0888 | G3: Mean | H3: 341.43505 | I3: Mean | J3: 9.995 | L3: 377.44929 | M3: 2
A4: 713.34 | B4: 285.34 | C4: 17 | E4: Standard Error | F4: 21.16185 | G4: Standard Error | H4: 9.6001196 | I4: Standard Error | J4: 0.39927683 | L4: 496.38857 | M4: 7
A5: 760.93 | B5: 161.7 | C5: 4 | E5: Median | F5: 976.72 | G5: Median | H5: 332.255 | I5: Median | J5: 10 | L5: 615.32786 | M5: 13
A6: 847 | B6: 271.04 | C6: 12 | E6: Mode | F6: #N/A | G6: Mode | H6: #N/A | I6: Mode | J6: 8 | L6: 734.26714 | M6: 19
A7: 965.64 | B7: 304.18 | C7: 8 | E7: Standard Deviation | F7: 299.27376 | G7: Standard Deviation | H7: 135.76619 | I7: Standard Deviation | J7: 5.646627 | L7: 853.20643 | M7: 28
A8: 1317.53 | B8: 312.91 | C8: 12 | E8: Sample Variance | F8: 89564.783 | G8: Sample Variance | H8: 18432.459 | I8: Sample Variance | J8: 31.884397 | L8: 972.14571 | M8: 29
A9: 1074.47 | B9: 300.85 | C9: 6 | E9: Kurtosis | F9: -0.088595232 | G9: Kurtosis | H9: 0.26450644 | I9: Kurtosis | J9: -1.2091054 | L9: 1091.085 | M9: 31
A10: 501.54 | B10: 190.59 | C10: 11 | E10: Skewness | F10: 0.14685797 | G10: Skewness | H10: 0.57339636 | I10: Skewness | J10: 0.060845864 | L10: 1210.0243 | M10: 28
A11: 737.31 | B11: 350.22 | C11: 2 | E11: Range | F11: 1665.15 | G11: Range | H11: 704.83 | I11: Range | J11: 18 | L11: 1328.9636 | M11: 17
A12: 1572.82 | B12: 672.38 | C12: 6 | E12: Minimum | F12: 258.51 | G12: Minimum | H12: 64.63 | I12: Minimum | J12: 1 | L12: 1447.9029 | M12: 11
A13: 1343.13 | B13: 456.66 | C13: 14 | E13: Maximum | F13: 1923.66 | G13: Maximum | H13: 769.46 | I13: Maximum | J13: 19 | L13: 1566.8421 | M13: 8
A14: 1191.58 | B14: 452.8 | C14: 14 | E14: Sum | F14: 195217.76 | G14: Sum | H14: 68287.01 | I14: Sum | J14: 1999 | L14: 1685.7814 | M14: 5
A15: 822.28 | B15: 273.41 | C15: 7 | E15: Count | F15: 200 | G15: Count | H15: 200 | I15: Count | J15: 200 | L15: 1804.7207 | M15: 0
A16: 521.67 | B16: 155.2 | C16: 15 | L16: More | M16: 1
A17: 1502.93 | B17: 300.59 | C17: 14
A18: 877.58 | B18: 298.38 | C18: 10
A19: 636.7 | B19: 203.74 | C19: 4
A20: 1506.14 | B20: 481.96 | C20: 13
A21: 645.02 | B21: 161.26 | C21: 4
A22: 953.3 | B22: 476.65 | C22: 11
A23: 388.56 | B23: 82.57 | C23: 14
A24: 743.17 | B24: 297.27 | C24: 9
A25: 706.37 | B25: 176.59 | C25: 6
A26: 925.31 | B26: 374.75 | C26: 8
A27: 1173.12 | B27: 293.28 | C27: 18
A28: 675.54 | B28: 236.44 | C28: 17
... A201: 928.32 | B201: 440.95 | C201: 2

Sheet Monthly Sales Growth
A1: Month | B1: Total Sales | C1: Growth | D1: Trend
A2: =DATE(2024,4,1) -> 45383 | B2: =SUMIFS(Dataset!$E:$E,Dataset!$H:$H,">="&A2,Dataset!$H:$H,"<"&EDATE(A2,1)) -> 19029.96
A3: =EDATE(A2,1) -> 45413 | B3: =SUMIFS(Dataset!$E:$E,Dataset!$H:$H,">="&A3,Dataset!$H:$H,"<"&EDATE(A3,1)) -> 18507.34 | C3: =IFERROR((B3-B2)/B2,0) -> -0.027463011 | D3: =IF(C3>0,"↑",IF(C3<0,"↓","→")) -> ↓
A4: =EDATE(A3,1) -> 45444 | B4: =SUMIFS(Dataset!$E:$E,Dataset!$H:$H,">="&A4,Dataset!$H:$H,"<"&EDATE(A4,1)) -> 20187.51 | C4: =IFERROR((B4-B3)/B3,0) -> 0.090783981 | D4: =IF(C4>0,"↑",IF(C4<0,"↓","→")) -> ↑
A5: =EDATE(A4,1) -> 45474 | B5: =SUMIFS(Dataset!$E:$E,Dataset!$H:$H,">="&A5,Dataset!$H:$H,"<"&EDATE(A5,1)) -> 11609.04 | C5: =IFERROR((B5-B4)/B4,0) -> -0.42493948 | D5: =IF(C5>0,"↑",IF(C5<0,"↓","→")) -> ↓
A6: =EDATE(A5,1) -> 45505 | B6: =SUMIFS(Dataset!$E:$E,Dataset!$H:$H,">="&A6,Dataset!$H:$H,"<"&EDATE(A6,1)) -> 10091.7 | C6: =IFERROR((B6-B5)/B5,0) -> -0.13070331 | D6: =IF(C6>0,"↑",IF(C6<0,"↓","→")) -> ↓
A7: =EDATE(A6,1) -> 45536 | B7: =SUMIFS(Dataset!$E:$E,Dataset!$H:$H,">="&A7,Dataset!$H:$H,"<"&EDATE(A7,1)) -> 20533.5 | C7: =IFERROR((B7-B6)/B6,0) -> 1.0346919 | D7: =IF(C7>0,"↑",IF(C7<0,"↓","→")) -> ↑
A8: =EDATE(A7,1) -> 45566 | B8: =SUMIFS(Dataset!$E:$E,Dataset!$H:$H,">="&A8,Dataset!$H:$H,"<"&EDATE(A8,1)) -> 14215.24 | C8: =IFERROR((B8-B7)/B7,0) -> -0.30770497 | D8: =IF(C8>0,"↑",IF(C8<0,"↓","→")) -> ↓
A9: =EDATE(A8,1) -> 45597 | B9: =SUMIFS(Dataset!$E:$E,Dataset!$H:$H,">="&A9,Dataset!$H:$H,"<"&EDATE(A9,1)) -> 20135.03 | C9: =IFERROR((B9-B8)/B8,0) -> 0.41643968 | D9: =IF(C9>0,"↑",IF(C9<0,"↓","→")) -> ↑
A10: =EDATE(A9,1) -> 45627 | B10: =SUMIFS(Dataset!$E:$E,Dataset!$H:$H,">="&A10,Dataset!$H:$H,"<"&EDATE(A10,1)) -> 11120.04 | C10: =IFERROR((B10-B9)/B9,0) -> -0.44772667 | D10: =IF(C10>0,"↑",IF(C10<0,"↓","→")) -> ↓
A11: =EDATE(A10,1) -> 45658 | B11: =SUMIFS(Dataset!$E:$E,Dataset!$H:$H,">="&A11,Dataset!$H:$H,"<"&EDATE(A11,1)) -> 14914.65 | C11: =IFERROR((B11-B10)/B10,0) -> 0.34124068 | D11: =IF(C11>0,"↑",IF(C11<0,"↓","→")) -> ↑
A12: =EDATE(A11,1) -> 45689 | B12: =SUMIFS(Dataset!$E:$E,Dataset!$H:$H,">="&A12,Dataset!$H:$H,"<"&EDATE(A12,1)) -> 14006.36 | C12: =IFERROR((B12-B11)/B11,0) -> -0.060899183 | D12: =IF(C12>0,"↑",IF(C12<0,"↓","→")) -> ↓
A13: =EDATE(A12,1) -> 45717 | B13: =SUMIFS(Dataset!$E:$E,Dataset!$H:$H,">="&A13,Dataset!$H:$H,"<"&EDATE(A13,1)) -> 17655.22 | C13: =IFERROR((B13-B12)/B12,0) -> 0.26051451 | D13: =IF(C13>0,"↑",IF(C13<0,"↓","→")) -> ↑
A14: =EDATE(A13,1) -> 45748 | B14: =SUMIFS(Dataset!$E:$E,Dataset!$H:$H,">="&A14,Dataset!$H:$H,"<"&EDATE(A14,1)) -> 3212.17 | C14: =IFERROR((B14-B13)/B13,0) -> -0.81806117 | D14: =IF(C14>0,"↑",IF(C14<0,"↓","→")) -> ↓

Sheet Timestamp Analysis
A1: TIMESTAMP ANALYSIS
A3: Last Updated Date & Time | B3: =NOW() -> 46325.437

Sheet High-Value Customer
A1: Customer_ID | B1: Total Sales | C1: Customer Rank | D1: Customer Category | F1: Top Customer Analysis
A2: ="CUST"&TEXT(ROW(A1),"000") -> CUST001 | B2: =SUMIF(Dataset!$A:$A,A2,Dataset!$E:$E) -> 6549.55 | C2: =_xlfn.RANK.EQ(B2,$B$2:$B$31,0) -> 15 | D2: =IF(C2<=10,"High Value","Regular") -> Regular | F2: Highest Sales | G2: =MAX(B2:B31) -> 11611.06
A3: ="CUST"&TEXT(ROW(A2),"000") -> CUST002 | B3: =SUMIF(Dataset!$A:$A,A3,Dataset!$E:$E) -> 6481.43 | C3: =_xlfn.RANK.EQ(B3,$B$2:$B$31,0) -> 17 | D3: =IF(C3<=10,"High Value","Regular") -> Regular | F3: Customer ID | G3: =INDEX(A2:A31,MATCH(G2,B2:B31,0)) -> CUST015
A4: ="CUST"&TEXT(ROW(A3),"000") -> CUST003 | B4: =SUMIF(Dataset!$A:$A,A4,Dataset!$E:$E) -> 8490.18 | C4: =_xlfn.RANK.EQ(B4,$B$2:$B$31,0) -> 7 | D4: =IF(C4<=10,"High Value","Regular") -> High Value | F4: Highest Sales | G4: =MAX(B2:B31) -> 11611.06
A5: ="CUST"&TEXT(ROW(A4),"000") -> CUST004 | B5: =SUMIF(Dataset!$A:$A,A5,Dataset!$E:$E) -> 7813.59 | C5: =_xlfn.RANK.EQ(B5,$B$2:$B$31,0) -> 10 | D5: =IF(C5<=10,"High Value","Regular") -> High Value | F5: Customer ID | G5: Customer ID
A6: ="CUST"&TEXT(ROW(A5),"000") -> CUST005 | B6: =SUMIF(Dataset!$A:$A,A6,Dataset!$E:$E) -> 6666.13 | C6: =_xlfn.RANK.EQ(B6,$B$2:$B$31,0) -> 14 | D6: =IF(C6<=10,"High Value","Regular") -> Regular
A7: ="CUST"&TEXT(ROW(A6),"000") -> CUST006 | B7: =SUMIF(Dataset!$A:$A,A7,Dataset!$E:$E) -> 2699.75 | C7: =_xlfn.RANK.EQ(B7,$B$2:$B$31,0) -> 30 | D7: =IF(C7<=10,"High Value","Regular") -> Regular
A8: ="CUST"&TEXT(ROW(A7),"000") -> CUST007 | B8: =SUMIF(Dataset!$A:$A,A8,Dataset!$E:$E) -> 9941.88 | C8: =_xlfn.RANK.EQ(B8,$B$2:$B$31,0) -> 3 | D8: =IF(C8<=10,"High Value","Regular") -> High Value
A9: ="CUST"&TEXT(ROW(A8),"000") -> CUST008 | B9: =SUMIF(Dataset!$A:$A,A9,Dataset!$E:$E) -> 9760.8 | C9: =_xlfn.RANK.EQ(B9,$B$2:$B$31,0) -> 4 | D9: =IF(C9<=10,"High Value","Regular") -> High Value
A10: ="CUST"&TEXT(ROW(A9),"000") -> CUST009 | B10: =SUMIF(Dataset!$A:$A,A10,Dataset!$E:$E) -> 6505.2 | C10: =_xlfn.RANK.EQ(B10,$B$2:$B$31,0) -> 16 | D10: =IF(C10<=10,"High Value","Regular") -> Regular
A11: ="CUST"&TEXT(ROW(A10),"000") -> CUST010 | B11: =SUMIF(Dataset!$A:$A,A11,Dataset!$E:$E) -> 4259.22 | C11: =_xlfn.RANK.EQ(B11,$B$2:$B$31,0) -> 24 | D11: =IF(C11<=10,"High Value","Regular") -> Regular
A12: ="CUST"&TEXT(ROW(A11),"000") -> CUST011 | B12: =SUMIF(Dataset!$A:$A,A12,Dataset!$E:$E) -> 3762.29 | C12: =_xlfn.RANK.EQ(B12,$B$2:$B$31,0) -> 27 | D12: =IF(C12<=10,"High Value","Regular") -> Regular
A13: ="CUST"&TEXT(ROW(A12),"000") -> CUST012 | B13: =SUMIF(Dataset!$A:$A,A13,Dataset!$E:$E) -> 8339 | C13: =_xlfn.RANK.EQ(B13,$B$2:$B$31,0) -> 8 | D13: =IF(C13<=10,"High Value","Regular") -> High Value
A14: ="CUST"&TEXT(ROW(A13),"000") -> CUST013 | B14: =SUMIF(Dataset!$A:$A,A14,Dataset!$E:$E) -> 4162.44 | C14: =_xlfn.RANK.EQ(B14,$B$2:$B$31,0) -> 25 | D14: =IF(C14<=10,"High Value","Regular") -> Regular
A15: ="CUST"&TEXT(ROW(A14),"000") -> CUST014 | B15: =SUMIF(Dataset!$A:$A,A15,Dataset!$E:$E) -> 6729.89 | C15: =_xlfn.RANK.EQ(B15,$B$2:$B$31,0) -> 12 | D15: =IF(C15<=10,"High Value","Regular") -> Regular
A16: ="CUST"&TEXT(ROW(A15),"000") -> CUST015 | B16: =SUMIF(Dataset!$A:$A,A16,Dataset!$E:$E) -> 11611.06 | C16: =_xlfn.RANK.EQ(B16,$B$2:$B$31,0) -> 1 | D16: =IF(C16<=10,"High Value","Regular") -> High Value
A17: ="CUST"&TEXT(ROW(A16),"000") -> CUST016 | B17: =SUMIF(Dataset!$A:$A,A17,Dataset!$E:$E) -> 3369.17 | C17: =_xlfn.RANK.EQ(B17,$B$2:$B$31,0) -> 29 | D17: =IF(C17<=10,"High Value","Regular") -> Regular
... A31: ="CUST"&TEXT(ROW(A30),"000") -> CUST030 | B31: =SUMIF(Dataset!$A:$A,A31,Dataset!$E:$E) -> 7928.71 | C31: =_xlfn.RANK.EQ(B31,$B$2:$B$31,0) -> 9 | D31: =IF(C31<=10,"High Value","Regular") -> High Value

Sheet Pivot Table
A3: Sum of Sales | B3: Column Labels
A4: Row Labels | B4: Books | C4: Clothing | D4: Electronics | E4: Furniture | F4: Office Supplies | G4: Grand Total
A5: Central | B5: 11297.15 | C5: 12200.26 | D5: 6621.24 | E5: 4876.96 | F5: 8472.72 | G5: 43468.33
A6: East | B6: 11389.09 | C6: 2401.45 | D6: 2869.54 | E6: 7592.34 | F6: 8189.22 | G6: 32441.64
A7: North | B7: 8037.01 | C7: 8422.82 | D7: 8191.71 | E7: 6978.08 | F7: 3345.8 | G7: 34975.42
A8: South | B8: 9588.04 | C8: 8393.63 | D8: 11989.07 | E8: 7982.73 | F8: 2295.32 | G8: 40248.79
A9: West | B9: 6691.17 | C9: 10509.43 | D9: 11372.44 | E9: 9182.78 | F9: 6327.76 | G9: 44083.58
A10: Grand Total | B10: 47002.46 | C10: 41927.59 | D10: 41044 | E10: 36612.89 | F10: 28630.82 | G10: 195217.76

Sheet Charts
A1: Sales by Region
A3: Region | B3: Total Sales
A4: Central | B4: =SUMIF(Dataset!$C:$C,A4,Dataset!$E:$E) -> 43468.33
A5: East | B5: =SUMIF(Dataset!$C:$C,A5,Dataset!$E:$E) -> 32441.64
A6: North | B6: =SUMIF(Dataset!$C:$C,A6,Dataset!$E:$E) -> 34975.42
A7: South | B7: =SUMIF(Dataset!$C:$C,A7,Dataset!$E:$E) -> 40248.79
A8: West | B8: =SUMIF(Dataset!$C:$C,A8,Dataset!$E:$E) -> 44083.58
A17: Month | B17: Total Sales
A18: =DATE(2024,4,1) -> 45383 | B18: =SUMIFS(Dataset!$E:$E,Dataset!$H:$H,">="&A18,Dataset!$H:$H,"<"&EDATE(A18,1)) -> 19029.96
A19: =EDATE(A18,1) -> 45413 | B19: =SUMIFS(Dataset!$E:$E,Dataset!$H:$H,">="&A19,Dataset!$H:$H,"<"&EDATE(A19,1)) -> 18507.34
A20: =EDATE(A19,1) -> 45444 | B20: =SUMIFS(Dataset!$E:$E,Dataset!$H:$H,">="&A20,Dataset!$H:$H,"<"&EDATE(A20,1)) -> 20187.51
A21: =EDATE(A20,1) -> 45474 | B21: =SUMIFS(Dataset!$E:$E,Dataset!$H:$H,">="&A21,Dataset!$H:$H,"<"&EDATE(A21,1)) -> 11609.04
A22: =EDATE(A21,1) -> 45505 | B22: =SUMIFS(Dataset!$E:$E,Dataset!$H:$H,">="&A22,Dataset!$H:$H,"<"&EDATE(A22,1)) -> 10091.7
A23: =EDATE(A22,1) -> 45536 | B23: =SUMIFS(Dataset!$E:$E,Dataset!$H:$H,">="&A23,Dataset!$H:$H,"<"&EDATE(A23,1)) -> 20533.5
A24: =EDATE(A23,1) -> 45566 | B24: =SUMIFS(Dataset!$E:$E,Dataset!$H:$H,">="&A24,Dataset!$H:$H,"<"&EDATE(A24,1)) -> 14215.24
A25: =EDATE(A24,1) -> 45597 | B25: =SUMIFS(Dataset!$E:$E,Dataset!$H:$H,">="&A25,Dataset!$H:$H,"<"&EDATE(A25,1)) -> 20135.03
A26: =EDATE(A25,1) -> 45627 | B26: =SUMIFS(Dataset!$E:$E,Dataset!$H:$H,">="&A26,Dataset!$H:$H,"<"&EDATE(A26,1)) -> 11120.04
A27: =EDATE(A26,1) -> 45658 | B27: =SUMIFS(Dataset!$E:$E,Dataset!$H:$H,">="&A27,Dataset!$H:$H,"<"&EDATE(A27,1)) -> 14914.65
A28: =EDATE(A27,1) -> 45689 | B28: =SUMIFS(Dataset!$E:$E,Dataset!$H:$H,">="&A28,Dataset!$H:$H,"<"&EDATE(A28,1)) -> 14006.36
A29: =EDATE(A28,1) -> 45717 | B29: =SUMIFS(Dataset!$E:$E,Dataset!$H:$H,">="&A29,Dataset!$H:$H,"<"&EDATE(A29,1)) -> 17655.22
A30: =EDATE(A29,1) -> 45748 | B30: =SUMIFS(Dataset!$E:$E,Dataset!$H:$H,">="&A30,Dataset!$H:$H,"<"&EDATE(A30,1)) -> 3212.17
A33: Product Category | B33: Total Sales
A34: Books | B34: =SUMIF(Dataset!$D:$D,A34,Dataset!$E:$E) -> 47002.46
A35: Clothing | B35: =SUMIF(Dataset!$D:$D,A35,Dataset!$E:$E) -> 41927.59
A36: Electronics | B36: =SUMIF(Dataset!$D:$D,A36,Dataset!$E:$E) -> 41044
A37: Furniture | B37: =SUMIF(Dataset!$D:$D,A37,Dataset!$E:$E) -> 36612.89
A38: Office Supplies | B38: =SUMIF(Dataset!$D:$D,A38,Dataset!$E:$E) -> 28630.82

Sheet Dashboard
A1: SALES PERFORMANCE ANALYTICS DASHBOARD
A4: Total Sales | D4: Total Profit | G4: Profit Margin | J4: Total Transactions
A5: =SUM(Dataset!E:E) -> 195217.76 | D5: =SUM(Dataset!I:I) -> 68287.01 | G5: =IFERROR(D5/A5,0) -> 0.34979917 | J5: =COUNT(Dataset!E:E) -> 200
A43: BUSINESS INSIGHTS
A45: Sales Performance:- | B45: The dataset contains 200 sales transactions, with an average transaction value of approximately ₹976.09.
A46: Profitability:- | B46: The average profit per transaction is approximately ₹341.44. The business should monitor profit margins alongside sales performance
A47: Customer Analysis:- | B47: The Top 10 customers have been identified based on total purchases. These customers can be prioritized for retention activities.
A48: Regional Performance:- | B48: The regional sales chart helps identify stronger and weaker sales regions for targeted business planning.
A49: Monthly Sales Trend:- | B49: Monthly sales growth analysis highlights periods of increasing and decreasing sales, supporting better forecasting and planning.
C54: BUSINESS RECOMMENDATION
B56: 1.Focus on retaining high-value customers thriugh personalised offers and loyalty programs.
B57: 2.Monitor discount policies to maintain profitability.
B58: 3.Develop targeted marketing strategies for lower-performing regions.
B59: 4.Review monthly sales trends to improve inventory and sales planning.
B60: 5.Use the dashboard regularly to monitor sales,profit,and business performance.
